2022-09-04 18:13:51,361 (13151/MainThread) litecli.main ERROR - sql: '.q', error: OperationalError('Not connected to database.')
2022-09-04 18:13:51,361 (13151/MainThread) litecli.main ERROR - traceback: 'Traceback (most recent call last):\n  File "/usr/lib/python3.10/site-packages/litecli/main.py", line 443, in one_iteration\n    for title, cur, headers, status in res:\n  File "/usr/lib/python3.10/site-packages/litecli/sqlexecute.py", line 115, in run\n    raise OperationalError("Not connected to database.")\nsqlite3.OperationalError: Not connected to database.\n'
2022-09-04 18:22:20,200 (19273/MainThread) litecli.main ERROR - sql: 'select * from peoples;', error: DatabaseError('file is not a database')
2022-09-04 18:22:20,201 (19273/MainThread) litecli.main ERROR - traceback: 'Traceback (most recent call last):\n  File "/usr/lib/python3.10/site-packages/litecli/sqlexecute.py", line 122, in run\n    for result in special.execute(cur, sql):\n  File "/usr/lib/python3.10/site-packages/litecli/packages/special/main.py", line 109, in execute\n    raise CommandNotFound\nlitecli.packages.special.main.CommandNotFound\n\nDuring handling of the above exception, another exception occurred:\n\nTraceback (most recent call last):\n  File "/usr/lib/python3.10/site-packages/litecli/main.py", line 443, in one_iteration\n    for title, cur, headers, status in res:\n  File "/usr/lib/python3.10/site-packages/litecli/sqlexecute.py", line 126, in run\n    cur.execute(sql)\nsqlite3.DatabaseError: file is not a database\n'
2022-09-04 18:22:25,984 (19273/MainThread) litecli.main ERROR - sql: 'tables', error: OperationalError('near "tables": syntax error')
2022-09-04 18:22:25,984 (19273/MainThread) litecli.main ERROR - traceback: 'Traceback (most recent call last):\n  File "/usr/lib/python3.10/site-packages/litecli/sqlexecute.py", line 122, in run\n    for result in special.execute(cur, sql):\n  File "/usr/lib/python3.10/site-packages/litecli/packages/special/main.py", line 109, in execute\n    raise CommandNotFound\nlitecli.packages.special.main.CommandNotFound\n\nDuring handling of the above exception, another exception occurred:\n\nTraceback (most recent call last):\n  File "/usr/lib/python3.10/site-packages/litecli/main.py", line 443, in one_iteration\n    for title, cur, headers, status in res:\n  File "/usr/lib/python3.10/site-packages/litecli/sqlexecute.py", line 126, in run\n    cur.execute(sql)\nsqlite3.OperationalError: near "tables": syntax error\n'
2022-09-04 18:22:27,399 (19273/MainThread) litecli.main ERROR - sql: '.tables', error: DatabaseError('file is not a database')
2022-09-04 18:22:27,400 (19273/MainThread) litecli.main ERROR - traceback: 'Traceback (most recent call last):\n  File "/usr/lib/python3.10/site-packages/litecli/main.py", line 443, in one_iteration\n    for title, cur, headers, status in res:\n  File "/usr/lib/python3.10/site-packages/litecli/sqlexecute.py", line 122, in run\n    for result in special.execute(cur, sql):\n  File "/usr/lib/python3.10/site-packages/litecli/packages/special/main.py", line 121, in execute\n    return special_cmd.handler(cur=cur, arg=arg, verbose=verbose)\n  File "/usr/lib/python3.10/site-packages/litecli/packages/special/dbcommands.py", line 43, in list_tables\n    cur.execute(query, args)\nsqlite3.DatabaseError: file is not a database\n'
2022-09-04 18:22:32,584 (19273/MainThread) litecli.main ERROR - sql: 'show tables;', error: OperationalError('near "show": syntax error')
2022-09-04 18:22:32,584 (19273/MainThread) litecli.main ERROR - traceback: 'Traceback (most recent call last):\n  File "/usr/lib/python3.10/site-packages/litecli/sqlexecute.py", line 122, in run\n    for result in special.execute(cur, sql):\n  File "/usr/lib/python3.10/site-packages/litecli/packages/special/main.py", line 109, in execute\n    raise CommandNotFound\nlitecli.packages.special.main.CommandNotFound\n\nDuring handling of the above exception, another exception occurred:\n\nTraceback (most recent call last):\n  File "/usr/lib/python3.10/site-packages/litecli/main.py", line 443, in one_iteration\n    for title, cur, headers, status in res:\n  File "/usr/lib/python3.10/site-packages/litecli/sqlexecute.py", line 126, in run\n    cur.execute(sql)\nsqlite3.OperationalError: near "show": syntax error\n'
2022-09-04 18:22:36,270 (19273/MainThread) litecli.main ERROR - sql: 'clear', error: OperationalError('near "clear": syntax error')
2022-09-04 18:22:36,271 (19273/MainThread) litecli.main ERROR - traceback: 'Traceback (most recent call last):\n  File "/usr/lib/python3.10/site-packages/litecli/sqlexecute.py", line 122, in run\n    for result in special.execute(cur, sql):\n  File "/usr/lib/python3.10/site-packages/litecli/packages/special/main.py", line 109, in execute\n    raise CommandNotFound\nlitecli.packages.special.main.CommandNotFound\n\nDuring handling of the above exception, another exception occurred:\n\nTraceback (most recent call last):\n  File "/usr/lib/python3.10/site-packages/litecli/main.py", line 443, in one_iteration\n    for title, cur, headers, status in res:\n  File "/usr/lib/python3.10/site-packages/litecli/sqlexecute.py", line 126, in run\n    cur.execute(sql)\nsqlite3.OperationalError: near "clear": syntax error\n'
2022-09-04 18:22:38,631 (19273/MainThread) litecli.main ERROR - sql: '.clear', error: OperationalError('near ".": syntax error')
2022-09-04 18:22:38,631 (19273/MainThread) litecli.main ERROR - traceback: 'Traceback (most recent call last):\n  File "/usr/lib/python3.10/site-packages/litecli/sqlexecute.py", line 122, in run\n    for result in special.execute(cur, sql):\n  File "/usr/lib/python3.10/site-packages/litecli/packages/special/main.py", line 109, in execute\n    raise CommandNotFound\nlitecli.packages.special.main.CommandNotFound\n\nDuring handling of the above exception, another exception occurred:\n\nTraceback (most recent call last):\n  File "/usr/lib/python3.10/site-packages/litecli/main.py", line 443, in one_iteration\n    for title, cur, headers, status in res:\n  File "/usr/lib/python3.10/site-packages/litecli/sqlexecute.py", line 126, in run\n    cur.execute(sql)\nsqlite3.OperationalError: near ".": syntax error\n'
2022-09-04 18:22:54,696 (19273/MainThread) litecli.main ERROR - sql: '.tables;', error: DatabaseError('file is not a database')
2022-09-04 18:22:54,696 (19273/MainThread) litecli.main ERROR - traceback: 'Traceback (most recent call last):\n  File "/usr/lib/python3.10/site-packages/litecli/main.py", line 443, in one_iteration\n    for title, cur, headers, status in res:\n  File "/usr/lib/python3.10/site-packages/litecli/sqlexecute.py", line 122, in run\n    for result in special.execute(cur, sql):\n  File "/usr/lib/python3.10/site-packages/litecli/packages/special/main.py", line 121, in execute\n    return special_cmd.handler(cur=cur, arg=arg, verbose=verbose)\n  File "/usr/lib/python3.10/site-packages/litecli/packages/special/dbcommands.py", line 43, in list_tables\n    cur.execute(query, args)\nsqlite3.DatabaseError: file is not a database\n'
2022-09-04 18:22:56,264 (19273/MainThread) litecli.main ERROR - sql: '.tables', error: DatabaseError('file is not a database')
2022-09-04 18:22:56,264 (19273/MainThread) litecli.main ERROR - traceback: 'Traceback (most recent call last):\n  File "/usr/lib/python3.10/site-packages/litecli/main.py", line 443, in one_iteration\n    for title, cur, headers, status in res:\n  File "/usr/lib/python3.10/site-packages/litecli/sqlexecute.py", line 122, in run\n    for result in special.execute(cur, sql):\n  File "/usr/lib/python3.10/site-packages/litecli/packages/special/main.py", line 121, in execute\n    return special_cmd.handler(cur=cur, arg=arg, verbose=verbose)\n  File "/usr/lib/python3.10/site-packages/litecli/packages/special/dbcommands.py", line 43, in list_tables\n    cur.execute(query, args)\nsqlite3.DatabaseError: file is not a database\n'
2022-09-04 18:23:03,032 (19273/MainThread) litecli.main ERROR - sql: 'select *;', error: OperationalError('no tables specified')
2022-09-04 18:23:03,032 (19273/MainThread) litecli.main ERROR - traceback: 'Traceback (most recent call last):\n  File "/usr/lib/python3.10/site-packages/litecli/sqlexecute.py", line 122, in run\n    for result in special.execute(cur, sql):\n  File "/usr/lib/python3.10/site-packages/litecli/packages/special/main.py", line 109, in execute\n    raise CommandNotFound\nlitecli.packages.special.main.CommandNotFound\n\nDuring handling of the above exception, another exception occurred:\n\nTraceback (most recent call last):\n  File "/usr/lib/python3.10/site-packages/litecli/main.py", line 443, in one_iteration\n    for title, cur, headers, status in res:\n  File "/usr/lib/python3.10/site-packages/litecli/sqlexecute.py", line 126, in run\n    cur.execute(sql)\nsqlite3.OperationalError: no tables specified\n'
2022-09-04 18:23:07,703 (19273/MainThread) litecli.main ERROR - sql: 'select * from peoples;', error: DatabaseError('file is not a database')
2022-09-04 18:23:07,704 (19273/MainThread) litecli.main ERROR - traceback: 'Traceback (most recent call last):\n  File "/usr/lib/python3.10/site-packages/litecli/sqlexecute.py", line 122, in run\n    for result in special.execute(cur, sql):\n  File "/usr/lib/python3.10/site-packages/litecli/packages/special/main.py", line 109, in execute\n    raise CommandNotFound\nlitecli.packages.special.main.CommandNotFound\n\nDuring handling of the above exception, another exception occurred:\n\nTraceback (most recent call last):\n  File "/usr/lib/python3.10/site-packages/litecli/main.py", line 443, in one_iteration\n    for title, cur, headers, status in res:\n  File "/usr/lib/python3.10/site-packages/litecli/sqlexecute.py", line 126, in run\n    cur.execute(sql)\nsqlite3.DatabaseError: file is not a database\n'
2022-09-09 10:02:44,944 (3190/MainThread) litecli.main ERROR - sql: 'show tables;', error: OperationalError('Not connected to database.')
2022-09-09 10:02:44,950 (3190/MainThread) litecli.main ERROR - traceback: 'Traceback (most recent call last):\n  File "/usr/lib/python3.10/site-packages/litecli/main.py", line 443, in one_iteration\n    for title, cur, headers, status in res:\n  File "/usr/lib/python3.10/site-packages/litecli/sqlexecute.py", line 115, in run\n    raise OperationalError("Not connected to database.")\nsqlite3.OperationalError: Not connected to database.\n'
2022-09-09 10:02:46,536 (3190/MainThread) litecli.main ERROR - sql: '.q', error: OperationalError('Not connected to database.')
2022-09-09 10:02:46,536 (3190/MainThread) litecli.main ERROR - traceback: 'Traceback (most recent call last):\n  File "/usr/lib/python3.10/site-packages/litecli/main.py", line 443, in one_iteration\n    for title, cur, headers, status in res:\n  File "/usr/lib/python3.10/site-packages/litecli/sqlexecute.py", line 115, in run\n    raise OperationalError("Not connected to database.")\nsqlite3.OperationalError: Not connected to database.\n'
2022-09-09 10:02:47,159 (3190/MainThread) litecli.main ERROR - sql: 'cls', error: OperationalError('Not connected to database.')
2022-09-09 10:02:47,159 (3190/MainThread) litecli.main ERROR - traceback: 'Traceback (most recent call last):\n  File "/usr/lib/python3.10/site-packages/litecli/main.py", line 443, in one_iteration\n    for title, cur, headers, status in res:\n  File "/usr/lib/python3.10/site-packages/litecli/sqlexecute.py", line 115, in run\n    raise OperationalError("Not connected to database.")\nsqlite3.OperationalError: Not connected to database.\n'
2022-09-09 10:02:48,823 (3190/MainThread) litecli.main ERROR - sql: '.q', error: OperationalError('Not connected to database.')
2022-09-09 10:02:48,824 (3190/MainThread) litecli.main ERROR - traceback: 'Traceback (most recent call last):\n  File "/usr/lib/python3.10/site-packages/litecli/main.py", line 443, in one_iteration\n    for title, cur, headers, status in res:\n  File "/usr/lib/python3.10/site-packages/litecli/sqlexecute.py", line 115, in run\n    raise OperationalError("Not connected to database.")\nsqlite3.OperationalError: Not connected to database.\n'
